Workbook
Name Αναλυτής_CategoryName: #N/A

Sheet Northwind dataset
A2: Δεδομένα της Northwind
A3: Suppliers | B3: Προμηθευτές και πωλητές της Northwind
A4: Customers | B4: Πελάτες που αγοράζουν προϊόντα από την Northwind
A5: Employees | B5: Στοιχεία υπαλλήλων της Northwind
A6: Products | B6: Πληροφορίες προϊόντος
A7: Shippers | B7: Τα στοιχεία των αποστολέων που αποστέλλουν τα προϊόντα από τους εμπόρους στους τελικούς πελάτες
A8: Orders and Order_Details | B8: Συναλλαγές παραγγελιών πωλήσεων που πραγματοποιούνται μεταξύ των πελατών και της εταιρείας

Sheet categories
A1: CategoryID | B1: CategoryName | C1: Description
A2: 1 | B2: Beverages | C2: Soft drinks, coffees, teas, beers, and ales
A3: 2 | B3: Condiments | C3: Sweet and savory sauces, relishes, spreads, and seasonings
A4: 3 | B4: Confections | C4: Desserts, candies, and sweet breads
A5: 4 | B5: Dairy Products | C5: Cheeses
A6: 5 | B6: Grains/Cereals | C6: Breads, crackers, pasta, and cereal
A7: 6 | B7: Meat/Poultry | C7: Prepared meats
A8: 7 | B8: Produce | C8: Dried fruit and bean curd
A9: 8 | B9: Seafood | C9: Seaweed and fish

Sheet customers
A1: CustomerID | B1: CustomerName | C1: ContactName | D1: Address | E1: City | F1: PostalCode | G1: Country
A2: 1 | B2: Alfreds Futterkiste | C2: Maria Anders | D2: Obere Str. 57 | E2: Berlin | F2: 12209 | G2: Germany
A3: 2 | B3: Ana Trujillo Emparedados y helados | C3: Ana Trujillo | D3: Avda. de la Constitucion 2222 | E3: Mexico D.F. | F3: 5021 | G3: Mexico
A4: 3 | B4: Antonio Moreno Taqueria | C4: Antonio Moreno | D4: Mataderos 2312 | E4: Mexico D.F. | F4: 5023 | G4: Mexico
A5: 4 | B5: Around the Horn | C5: Thomas Hardy | D5: 120 Hanover Sq. | E5: London | F5: WA1 1DP | G5: UK
A6: 5 | B6: Berglunds snabbkop | C6: Christina Berglund | D6: Berguvsvagen 8 | E6: Lulea | F6: S-958 22 | G6: Sweden
A7: 6 | B7: Blauer See Delikatessen | C7: Hanna Moos | D7: Forsterstr. 57 | E7: Mannheim | F7: 68306 | G7: Germany
A8: 7 | B8: Blondel pere et fils | C8: Frederique Citeaux | D8: 24, place Kleber | E8: Strasbourg | F8: 67000 | G8: France
A9: 8 | B9: Bolido Comidas preparadas | C9: Martin Sommer | D9: C/ Araquil, 67 | E9: Madrid | F9: 28023 | G9: Spain
A10: 9 | B10: Bon app'' | C10: Laurence Lebihans | D10: 12, rue des Bouchers | E10: Marseille | F10: 13008 | G10: France
A11: 10 | B11: Bottom-Dollar Marketse | C11: Elizabeth Lincoln | D11: 23 Tsawassen Blvd. | E11: Tsawassen | F11: T2F 8M4 | G11: Canada
A12: 11 | B12: B''s Beverages | C12: Victoria Ashworth | D12: Fauntleroy Circus | E12: London | F12: EC2 5NT | G12: UK
A13: 12 | B13: Cactus Comidas para llevar | C13: Patricio Simpson | D13: Cerrito 333 | E13: Buenos Aires | F13: 1010 | G13: Argentina
A14: 13 | B14: Centro comercial Moctezuma | C14: Francisco Chang | D14: Sierras de Granada 9993 | E14: Mexico D.F. | F14: 5022 | G14: Mexico
A15: 14 | B15: Chop-suey Chinese | C15: Yang Wang | D15: Hauptstr. 29 | E15: Bern | F15: 3012 | G15: Switzerland
A16: 15 | B16: Comercio Mineiro | C16: Pedro Afonso | D16: Av. dos Lusiadas, 23 | E16: Sao Paulo | F16: 05432-043 | G16: Brazil
A17: 16 | B17: Consolidated Holdings | C17: Elizabeth Brown | D17: Berkeley Gardens 12 Brewery | E17: London | F17: WX1 6LT | G17: UK
A18: 17 | B18: Drachenblut Delikatessend | C18: Sven Ottlieb | D18: Walserweg 21 | E18: Aachen | F18: 52066 | G18: Germany
A19: 18 | B19: Du monde entier | C19: Janine Labrune | D19: 67, rue des Cinquante Otages | E19: Nantes | F19: 44000 | G19: France
A20: 19 | B20: Eastern Connection | C20: Ann Devon | D20: 35 King George | E20: London | F20: WX3 6FW | G20: UK
A21: 20 | B21: Ernst Handel | C21: Roland Mendel | D21: Kirchgasse 6 | E21: Graz | F21: 8010 | G21: Austria
A22: 21 | B22: Familia Arquibaldo | C22: Aria Cruz | D22: Rua Oros, 92 | E22: Sao Paulo | F22: 05442-030 | G22: Brazil
A23: 22 | B23: FISSA Fabrica Inter. Salchichas S.A. | C23: Diego Roel | D23: C/ Moralzarzal, 86 | E23: Madrid | F23: 28034 | G23: Spain
A24: 23 | B24: Folies gourmandes | C24: Martine Rance | D24: 184, chaussee de Tournai | E24: Lille | F24: 59000 | G24: France
A25: 24 | B25: Folk och fa HB | C25: Maria Larsson | D25: Akergatan 24 | E25: Bracke | F25: S-844 67 | G25: Sweden
A26: 25 | B26: Frankenversand | C26: Peter Franken | D26: Berliner Platz 43 | E26: Munchen | F26: 80805 | G26: Germany
A27: 26 | B27: France restauration | C27: Carine Schmitt | D27: 54, rue Royale | E27: Nantes | F27: 44000 | G27: France
A28: 27 | B28: Franchi S.p.A. | C28: Paolo Accorti | D28: Via Monte Bianco 34 | E28: Torino | F28: 10100 | G28: Italy
A29: 28 | B29: Furia Bacalhau e Frutos do Mar | C29: Lino Rodriguez | D29: Jardim das rosas n. 32 | E29: Lisboa | F29: 1675 | G29: Portugal
A30: 29 | B30: Galeria del gastronomo | C30: Eduardo Saavedra | D30: Rambla de Cataluna, 23 | E30: Barcelona | F30: 8022 | G30: Spain
A31: 30 | B31: Godos Cocina Tipica | C31: Jose Pedro Freyre | D31: C/ Romero, 33 | E31: Sevilla | F31: 41101 | G31: Spain
A32: 31 | B32: Gourmet Lanchonetes | C32: Andre Fonseca | D32: Av. Brasil, 442 | E32: Campinas | F32: 04876-786 | G32: Brazil
A33: 32 | B33: Great Lakes Food Market | C33: Howard Snyder | D33: 2732 Baker Blvd. | E33: Eugene | F33: 97403 | G33: USA
A34: 33 | B34: GROSELLA-Restaurante | C34: Manuel Pereira | D34: 5a Ave. Los Palos Grandes | E34: Caracas | F34: 1081 | G34: Venezuela
A35: 34 | B35: Hanari Carnes | C35: Mario Pontes | D35: Rua do Paco, 67 | E35: Rio de Janeiro | F35: 05454-876 | G35: Brazil
A36: 35 | B36: HILARION-Abastos | C36: Carlos Hernandez | D36: Carrera 22 con Ave. Carlos Soublette #8-35 | E36: San Cristobal | F36: 5022 | G36: Venezuela
A37: 36 | B37: Hungry Coyote Import Store | C37: Yoshi Latimer | D37: City Center Plaza 516 Main St. | E37: Elgin | F37: 97827 | G37: USA
A38: 37 | B38: Hungry Owl All-Night Grocers | C38: Patricia McKenna | D38: 8 Johnstown Road | E38: Cork | G38: Ireland
A39: 38 | B39: Island Trading | C39: Helen Bennett | D39: Garden House Crowther Way | E39: Cowes | F39: PO31 7PJ | G39: UK
A40: 39 | B40: Koniglich Essen | C40: Philip Cramer | D40: Maubelstr. 90 | E40: Brandenburg | F40: 14776 | G40: Germany
...

Sheet employees
A1: EmployeeID | B1: LastName | C1: FirstName | D1: BirthDate | E1: Photo | F1: Notes
A2: 1 | B2: Davolio | C2: Nancy | D2: 25180 | E2: EmpID1.pic | F2: Education includes a BA in psychology from Colorado State University. She also completed (The Art of the Cold Call). Nancy is a member of 'Toastmasters International'.
A3: 2 | B3: Fuller | C3: Andrew | D3: 19043 | E3: EmpID2.pic | F3: Andrew received his BTS commercial and a Ph.D. in international marketing from the University of Dallas. He is fluent in French and Italian and reads German. He joined the company as a sales representative, was promoted to sales manager and was then named vice president of sales. Andrew is a member of the Sales Management Roundtable, the Seattle Chamber of Commerce, and the Pacific Rim Importers Association.
A4: 3 | B4: Leverling | C4: Janet | D4: 23253 | E4: EmpID3.pic | F4: Janet has a BS degree in chemistry from Boston College). She has also completed a certificate program in food retailing management. Janet was hired as a sales associate and was promoted to sales representative.
A5: 4 | B5: Peacock | C5: Margaret | D5: 21447 | E5: EmpID4.pic | F5: Margaret holds a BA in English literature from Concordia College and an MA from the American Institute of Culinary Arts. She was temporarily assigned to the London office before returning to her permanent post in Seattle.
A6: 5 | B6: Buchanan | C6: Steven | D6: 20152 | E6: EmpID5.pic | F6: Steven Buchanan graduated from St. Andrews University, Scotland, with a BSC degree. Upon joining the company as a sales representative, he spent 6 months in an orientation program at the Seattle office and then returned to his permanent post in London, where he was promoted to sales manager. Mr. Buchanan has completed the courses 'Successful Telemarketing' and 'International Sales Management'. He is fluent in French.
A7: 6 | B7: Suyama | C7: Michael | D7: 23194 | E7: EmpID6.pic | F7: Michael is a graduate of Sussex University (MA, economics) and the University of California at Los Angeles (MBA, marketing). He has also taken the courses 'Multi-Cultural Selling' and 'Time Management for the Sales Professional'. He is fluent in Japanese and can read and write French, Portuguese, and Spanish.
A8: 7 | B8: King | C8: Robert | D8: 22065 | E8: EmpID7.pic | F8: Robert King served in the Peace Corps and traveled extensively before completing his degree in English at the University of Michigan and then joining the company. After completing a course entitled 'Selling in Europe', he was transferred to the London office.
A9: 8 | B9: Callahan | C9: Laura | D9: 21194 | E9: EmpID8.pic | F9: Laura received a BA in psychology from the University of Washington. She has also completed a course in business French. She reads and writes French.
A10: 9 | B10: Dodsworth | C10: Anne | D10: 25386 | E10: EmpID9.pic | F10: Anne has a BA degree in English from St. Lawrence College. She is fluent in French and German.
A11: 10 | B11: West | C11: Adam | D11: 10490 | E11: EmpID10.pic | F11: An old chum.

Sheet orderdetails
A1: OrderDetailID | B1: OrderID | C1: ProductID | D1: Quantity
A2: 1 | B2: 10248 | C2: 11 | D2: 12
A3: 2 | B3: 10248 | C3: 42 | D3: 10
A4: 3 | B4: 10248 | C4: 72 | D4: 5
A5: 4 | B5: 10249 | C5: 14 | D5: 9
A6: 5 | B6: 10249 | C6: 51 | D6: 40
A7: 6 | B7: 10250 | C7: 41 | D7: 10
A8: 7 | B8: 10250 | C8: 51 | D8: 35
A9: 8 | B9: 10250 | C9: 65 | D9: 15
A10: 9 | B10: 10251 | C10: 22 | D10: 6
A11: 10 | B11: 10251 | C11: 57 | D11: 15
A12: 11 | B12: 10251 | C12: 65 | D12: 20
A13: 12 | B13: 10252 | C13: 20 | D13: 40
... A519: 518 | B519: 10443 | C519: 28 | D519: 12

Sheet orders
A1: OrderID | B1: CustomerID | C1: EmployeeID | D1: OrderDate | E1: ShipperID | F1: Column1 | G1: VLOOKUP | H1: XLOOKUP
A2: 10248 | B2: 90 | C2: 5 | D2: 35250 | E2: 3 | F2: =IF(OR(Πίνακας6[[#This Row],[ShipperID]]=1,Πίνακας6[[#This Row],[ShipperID]]=3),"Fast shipping lane","Standard shipping") -> Fast shipping lane | G2: =VLOOKUP(Πίνακας6[[#This Row],[ShipperID]],Πίνακας8[#All],2,FALSE) -> Federal Shipping | H2: =_xlfn.XLOOKUP(Πίνακας6[[#This Row],[ShipperID]],shippers!A:A,shippers!B:B,,FALSE) -> Federal Shipping
A3: 10249 | B3: 81 | C3: 6 | D3: 35251 | E3: 1 | F3: =IF(OR(Πίνακας6[[#This Row],[ShipperID]]=1,Πίνακας6[[#This Row],[ShipperID]]=3),"Fast shipping lane","Standard shipping") -> Fast shipping lane | G3: =VLOOKUP(Πίνακας6[[#This Row],[ShipperID]],Πίνακας8[#All],2,FALSE) -> Speedy Express | H3: =_xlfn.XLOOKUP(Πίνακας6[[#This Row],[ShipperID]],shippers!A:A,shippers!B:B,,FALSE) -> Speedy Express
A4: 10250 | B4: 34 | C4: 4 | D4: 35254 | E4: 2 | F4: =IF(OR(Πίνακας6[[#This Row],[ShipperID]]=1,Πίνακας6[[#This Row],[ShipperID]]=3),"Fast shipping lane","Standard shipping") -> Standard shipping | G4: =VLOOKUP(Πίνακας6[[#This Row],[ShipperID]],Πίνακας8[#All],2,FALSE) -> United Package | H4: =_xlfn.XLOOKUP(Πίνακας6[[#This Row],[ShipperID]],shippers!A:A,shippers!B:B,,FALSE) -> United Package
A5: 10251 | B5: 84 | C5: 3 | D5: 35254 | E5: 1 | F5: =IF(OR(Πίνακας6[[#This Row],[ShipperID]]=1,Πίνακας6[[#This Row],[ShipperID]]=3),"Fast shipping lane","Standard shipping") -> Fast shipping lane | G5: =VLOOKUP(Πίνακας6[[#This Row],[ShipperID]],Πίνακας8[#All],2,FALSE) -> Speedy Express | H5: =_xlfn.XLOOKUP(Πίνακας6[[#This Row],[ShipperID]],shippers!A:A,shippers!B:B,,FALSE) -> Speedy Express
A6: 10252 | B6: 76 | C6: 4 | D6: 35255 | E6: 2 | F6: =IF(OR(Πίνακας6[[#This Row],[ShipperID]]=1,Πίνακας6[[#This Row],[ShipperID]]=3),"Fast shipping lane","Standard shipping") -> Standard shipping | G6: =VLOOKUP(Πίνακας6[[#This Row],[ShipperID]],Πίνακας8[#All],2,FALSE) -> United Package | H6: =_xlfn.XLOOKUP(Πίνακας6[[#This Row],[ShipperID]],shippers!A:A,shippers!B:B,,FALSE) -> United Package
A7: 10253 | B7: 34 | C7: 3 | D7: 35256 | E7: 2 | F7: =IF(OR(Πίνακας6[[#This Row],[ShipperID]]=1,Πίνακας6[[#This Row],[ShipperID]]=3),"Fast shipping lane","Standard shipping") -> Standard shipping | G7: =VLOOKUP(Πίνακας6[[#This Row],[ShipperID]],Πίνακας8[#All],2,FALSE) -> United Package | H7: =_xlfn.XLOOKUP(Πίνακας6[[#This Row],[ShipperID]],shippers!A:A,shippers!B:B,,FALSE) -> United Package
A8: 10254 | B8: 14 | C8: 5 | D8: 35257 | E8: 2 | F8: =IF(OR(Πίνακας6[[#This Row],[ShipperID]]=1,Πίνακας6[[#This Row],[ShipperID]]=3),"Fast shipping lane","Standard shipping") -> Standard shipping | G8: =VLOOKUP(Πίνακας6[[#This Row],[ShipperID]],Πίνακας8[#All],2,FALSE) -> United Package | H8: =_xlfn.XLOOKUP(Πίνακας6[[#This Row],[ShipperID]],shippers!A:A,shippers!B:B,,FALSE) -> United Package
A9: 10255 | B9: 68 | C9: 9 | D9: 35258 | E9: 3 | F9: =IF(OR(Πίνακας6[[#This Row],[ShipperID]]=1,Πίνακας6[[#This Row],[ShipperID]]=3),"Fast shipping lane","Standard shipping") -> Fast shipping lane | G9: =VLOOKUP(Πίνακας6[[#This Row],[ShipperID]],Πίνακας8[#All],2,FALSE) -> Federal Shipping | H9: =_xlfn.XLOOKUP(Πίνακας6[[#This Row],[ShipperID]],shippers!A:A,shippers!B:B,,FALSE) -> Federal Shipping
A10: 10256 | B10: 88 | C10: 3 | D10: 35261 | E10: 2 | F10: =IF(OR(Πίνακας6[[#This Row],[ShipperID]]=1,Πίνακας6[[#This Row],[ShipperID]]=3),"Fast shipping lane","Standard shipping") -> Standard shipping | G10: =VLOOKUP(Πίνακας6[[#This Row],[ShipperID]],Πίνακας8[#All],2,FALSE) -> United Package | H10: =_xlfn.XLOOKUP(Πίνακας6[[#This Row],[ShipperID]],shippers!A:A,shippers!B:B,,FALSE) -> United Package
A11: 10257 | B11: 35 | C11: 4 | D11: 35262 | E11: 3 | F11: =IF(OR(Πίνακας6[[#This Row],[ShipperID]]=1,Πίνακας6[[#This Row],[ShipperID]]=3),"Fast shipping lane","Standard shipping") -> Fast shipping lane | G11: =VLOOKUP(Πίνακας6[[#This Row],[ShipperID]],Πίνακας8[#All],2,FALSE) -> Federal Shipping | H11: =_xlfn.XLOOKUP(Πίνακας6[[#This Row],[ShipperID]],shippers!A:A,shippers!B:B,,FALSE) -> Federal Shipping
A12: 10258 | B12: 20 | C12: 1 | D12: 35263 | E12: 1 | F12: =IF(OR(Πίνακας6[[#This Row],[ShipperID]]=1,Πίνακας6[[#This Row],[ShipperID]]=3),"Fast shipping lane","Standard shipping") -> Fast shipping lane | G12: =VLOOKUP(Πίνακας6[[#This Row],[ShipperID]],Πίνακας8[#All],2,FALSE) -> Speedy Express | H12: =_xlfn.XLOOKUP(Πίνακας6[[#This Row],[ShipperID]],shippers!A:A,shippers!B:B,,FALSE) -> Speedy Express
A13: 10259 | B13: 13 | C13: 4 | D13: 35264 | E13: 3 | F13: =IF(OR(Πίνακας6[[#This Row],[ShipperID]]=1,Πίνακας6[[#This Row],[ShipperID]]=3),"Fast shipping lane","Standard shipping") -> Fast shipping lane | G13: =VLOOKUP(Πίνακας6[[#This Row],[ShipperID]],Πίνακας8[#All],2,FALSE) -> Federal Shipping | H13: =_xlfn.XLOOKUP(Πίνακας6[[#This Row],[ShipperID]],shippers!A:A,shippers!B:B,,FALSE) -> Federal Shipping
... A197: 10443 | B197: 66 | C197: 8 | D197: 35473 | E197: 1 | F197: =IF(OR(Πίνακας6[[#This Row],[ShipperID]]=1,Πίνακας6[[#This Row],[ShipperID]]=3),"Fast shipping lane","Standard shipping") -> Fast shipping lane | G197: =VLOOKUP(Πίνακας6[[#This Row],[ShipperID]],Πίνακας8[#All],2,FALSE) -> Speedy Express | H197: =_xlfn.XLOOKUP(Πίνακας6[[#This Row],[ShipperID]],shippers!A:A,shippers!B:B,,FALSE) -> Speedy Express

Sheet orders1
A1: OrderID | B1: CustomerID | C1: EmployeeID | D1: OrderDate | E1: ShipperID
A2: 10248 | B2: 90 | C2: 5 | D2: 35250 | E2: 3
A3: 10249 | B3: 81 | C3: 6 | D3: 35251 | E3: 1
A4: 10250 | B4: 34 | C4: 4 | D4: 35254 | E4: 2
A5: 10251 | B5: 84 | C5: 3 | D5: 35254 | E5: 1
A6: 10252 | B6: 76 | C6: 4 | D6: 35255 | E6: 2
A7: 10253 | B7: 34 | C7: 3 | D7: 35256 | E7: 2
A8: 10254 | B8: 14 | C8: 5 | D8: 35257 | E8: 2
A9: 10255 | B9: 68 | C9: 9 | D9: 35258 | E9: 3
A10: 10256 | B10: 88 | C10: 3 | D10: 35261 | E10: 2
A11: 10257 | B11: 35 | C11: 4 | D11: 35262 | E11: 3
A12: 10258 | B12: 20 | C12: 1 | D12: 35263 | E12: 1
A13: 10259 | B13: 13 | C13: 4 | D13: 35264 | E13: 3
... A197: 10443 | B197: 66 | C197: 8 | D197: 35473 | E197: 1

Sheet products
A1: ProductID | B1: ProductName | C1: SupplierID | D1: CategoryID | E1: Unit | F1: Price
A2: 1 | B2: Chais | C2: 1 | D2: 1 | E2: 10 boxes x 20 bags | F2: 18
A3: 2 | B3: Chang | C3: 1 | D3: 1 | E3: 24 - 12 oz bottles | F3: 19
A4: 3 | B4: Aniseed Syrup | C4: 1 | D4: 2 | E4: 12 - 550 ml bottles | F4: 10
A5: 4 | B5: Chef Anton's Cajun Seasoning | C5: 2 | D5: 2 | E5: 48 - 6 oz jars | F5: 22
A6: 5 | B6: Chef Anton's Gumbo Mix | C6: 2 | D6: 2 | E6: 36 boxes | F6: 21
A7: 6 | B7: Grandma's Boysenberry Spread | C7: 3 | D7: 2 | E7: 12 - 8 oz jars | F7: 25
A8: 7 | B8: Uncle Bob's Organic Dried Pears | C8: 3 | D8: 7 | E8: 12 - 1 lb pkgs. | F8: 30
A9: 8 | B9: Northwoods Cranberry Sauce | C9: 3 | D9: 2 | E9: 12 - 12 oz jars | F9: 40
A10: 9 | B10: Mishi Kobe Niku | C10: 4 | D10: 6 | E10: 18 - 500 g pkgs. | F10: 97
A11: 10 | B11: Ikura | C11: 4 | D11: 8 | E11: 12 - 200 ml jars | F11: 31
A12: 11 | B12: Queso Cabrales | C12: 5 | D12: 4 | E12: 1 kg pkg. | F12: 21
A13: 12 | B13: Queso Manchego La Pastora | C13: 5 | D13: 4 | E13: 10 - 500 g pkgs. | F13: 38
... A78: 77 | B78: Original Frankfurter grune So├ƒe | C78: 12 | D78: 2 | E78: 12 boxes | F78: 13

Sheet shippers
A1: ShipperID | B1: ShipperName | C1: Phone
A2: 1 | B2: Speedy Express | C2: (503) 555-9831
A3: 2 | B3: United Package | C3: (503) 555-3199
A4: 3 | B4: Federal Shipping | C4: (503) 555-9931

Sheet suppliers
A1: SupplierID | B1: SupplierName | C1: ContactName | D1: Address | E1: City | F1: PostalCode | G1: Country | H1: Phone
A2: 1 | B2: Exotic Liquid | C2: Charlotte Cooper | D2: 49 Gilbert St. | E2: Londona | F2: EC1 4SD | G2: UK | H2: (171) 555-2222
A3: 2 | B3: New Orleans Cajun Delights | C3: Shelley Burke | D3: P.O. Box 78934 | E3: New Orleans | F3: 70117 | G3: USA | H3: (100) 555-4822
A4: 3 | B4: Grandma Kelly's Homestead | C4: Regina Murphy | D4: 707 Oxford Rd. | E4: Ann Arbor | F4: 48104 | G4: USA | H4: (313) 555-5735
A5: 4 | B5: Tokyo Traders | C5: Yoshi Nagase | D5: 9-8 Sekimai Musashino-shi | E5: Tokyo | F5: 100 | G5: Japan | H5: (03) 3555-5011
A6: 5 | B6: Cooperativa de Quesos 'Las Cabras' | C6: Antonio del Valle Saavedra | D6: Calle del Rosal 4 | E6: Oviedo | F6: 33007 | G6: Spain | H6: (98) 598 76 54
A7: 6 | B7: Mayumi's | C7: Mayumi Ohno | D7: 92 Setsuko Chuo-ku | E7: Osaka | F7: 545 | G7: Japan | H7: (06) 431-7877
A8: 7 | B8: Pavlova, Ltd. | C8: Ian Devling | D8: 74 Rose St. Moonie Ponds | E8: Melbourne | F8: 3058 | G8: Australia | H8: (03) 444-2343
A9: 8 | B9: Specialty Biscuits, Ltd. | C9: Peter Wilson | D9: 29 King's Way | E9: Manchester | F9: M14 GSD | G9: UK | H9: (161) 555-4448
A10: 9 | B10: PB Knackebrod AB | C10: Lars Peterson | D10: Kaloadagatan 13 | E10: Goteborg | F10: S-345 67 | G10: Sweden | H10: 031-987 65 43
A11: 10 | B11: Refrescos Americanas LTDA | C11: Carlos Diaz | D11: Av. das Americanas 12.890 | E11: Sao Paulo | F11: 5442 | G11: Brazil | H11: (11) 555 4640
A12: 11 | B12: Heli Su├ƒwaren GmbH & Co. KG | C12: Petra Winkler | D12: Tiergartenstra├ƒe 5 | E12: Berlin | F12: 10785 | G12: Germany | H12: (010) 9984510
A13: 12 | B13: Plutzer Lebensmittelgro├ƒmarkte AG | C13: Martin Bein | D13: Bogenallee 51 | E13: Frankfurt | F13: 60439 | G13: Germany | H13: (069) 992755
A14: 13 | B14: Nord-Ost-Fisch Handelsgesellschaft mbH | C14: Sven Petersen | D14: Frahmredder 112a | E14: Cuxhaven | F14: 27478 | G14: Germany | H14: (04721) 8713
A15: 14 | B15: Formaggi Fortini s.r.l. | C15: Elio Rossi | D15: Viale Dante, 75 | E15: Ravenna | F15: 48100 | G15: Italy | H15: (0544) 60323
A16: 15 | B16: Norske Meierier | C16: Beate Vileid | D16: Hatlevegen 5 | E16: Sandvika | F16: 1320 | G16: Norway | H16: (0)2-953010
A17: 16 | B17: Bigfoot Breweries | C17: Cheryl Saylor | D17: 3400 - 8th Avenue Suite 210 | E17: Bend | F17: 97101 | G17: USA | H17: (503) 555-9931
A18: 17 | B18: Svensk Sjofoda AB | C18: Michael Bjorn | D18: Brovallavagen 231 | E18: Stockholm | F18: S-123 45 | G18: Sweden | H18: 08-123 45 67
A19: 18 | B19: Aux joyeux ecclesiastiques | C19: Guylene Nodier | D19: 203, Rue des Francs-Bourgeois | E19: Paris | F19: 75004 | G19: France | H19: (1) 03.83.00.68
A20: 19 | B20: New England Seafood Cannery | C20: Robb Merchant | D20: Order Processing Dept. 2100 Paul Revere Blvd. | E20: Boston | F20: 2134 | G20: USA | H20: (617) 555-3267
A21: 20 | B21: Leka Trading | C21: Chandra Leka | D21: 471 Serangoon Loop, Suite #402 | E21: Singapore | F21: 512 | G21: Singapore | H21: 555-8787
A22: 21 | B22: Lyngbysild | C22: Niels Petersen | D22: Lyngbysild Fiskebakken 10 | E22: Lyngby | F22: 2800 | G22: Denmark | H22: 43844108
A23: 22 | B23: Zaanse Snoepfabriek | C23: Dirk Luchte | D23: Verkoop Rijnweg 22 | E23: Zaandam | F23: 9999 ZZ | G23: Netherlands | H23: (12345) 1212
A24: 23 | B24: Karkki Oy | C24: Anne Heikkonen | D24: Valtakatu 12 | E24: Lappeenranta | F24: 53120 | G24: Finland | H24: (953) 10956
A25: 24 | B25: G'day, Mate | C25: Wendy Mackenzie | D25: 170 Prince Edward Parade Hunter's Hill | E25: Sydney | F25: 2042 | G25: Australia | H25: (02) 555-5914
A26: 25 | B26: Ma Maison | C26: Jean-Guy Lauzon | D26: 2960 Rue St. Laurent | E26: Montreal | F26: H1J 1C3 | G26: Canada | H26: (514) 555-9022
A27: 26 | B27: Pasta Buttini s.r.l. | C27: Giovanni Giudici | D27: Via dei Gelsomini, 153 | E27: Salerno | F27: 84100 | G27: Italy | H27: (089) 6547665
A28: 27 | B28: Escargots Nouveaux | C28: Marie Delamare | D28: 22, rue H. Voiron | E28: Montceau | F28: 71300 | G28: France | H28: 85.57.00.07
A29: 28 | B29: Gai paturage | C29: Eliane Noz | D29: Bat. B 3, rue des Alpes | E29: Annecy | F29: 74000 | G29: France | H29: 38.76.98.06
A30: 29 | B30: Forets d'erables | C30: Chantal Goulet | D30: 148 rue Chasseur | E30: Ste-Hyacinthe | F30: J2S 7S8 | G30: Canada | H30: (514) 555-2955

Sheet ΟΔΗΓΙΕΣ
A1: 📘 Μεγάλη Άσκηση Data Analysis Excel (Northwind) — Διάρκεια ~60–90 λεπτά
A2: Οδηγίες: | B2: Χρησιμοποίησε τα φύλλα δεδομένων (products, suppliers, orders, orderdetails, customers, categories, shippers, employees). Στα φύλλα 01_ΕΡΓΑΣΤΗΡΙΟ, 02_FACTS και 03_PIVOT υπάρχουν έτοιμες περιοχές εργασίας.
A5: # | B5: Ενότητα | C5: Ερώτημα / Ζητούμενο | D5: Δεδομένα (φύλλο) | E5: Κελί εργασίας | F5: Συνάρτηση/Εργαλείο
A6: 1 | B6: 1. Μέτρα θέσης/διασποράς | C6: Υπολόγισε ΜΕΣΟ ΟΡΟ τιμής (Price) για το δείγμα 25 προϊόντων (tbl_ProductsView). | D6: products | E6: 01_ΕΡΓΑΣΤΗΡΙΟ!B7 | F6: .
A7: 2 | B7: 1. Μέτρα θέσης/διασποράς | C7: Υπολόγισε ΔΙΑΜΕΣΟ (Median) τιμής (Price) για το δείγμα 25 προϊόντων (tbl_ProductsView). | D7: products | E7: 01_ΕΡΓΑΣΤΗΡΙΟ!B8 | F7: .
A8: 3 | B8: 1. Μέτρα θέσης/διασποράς | C8: Υπολόγισε ΕΠΙΚΡΑΤΟΥΣΑ ΤΙΜΗ (Mode) τιμής (Price) για το δείγμα 25 προϊόντων (tbl_ProductsView). | D8: products | E8: 01_ΕΡΓΑΣΤΗΡΙΟ!B9 | F8: .
A9: 4 | B9: 1. Μέτρα θέσης/διασποράς | C9: Υπολόγισε ΤΥΠΙΚΗ ΑΠΟΚΛΙΣΗ (STDEV.S) τιμής (Price) για το δείγμα 25 προϊόντων (tbl_ProductsView). | D9: products | E9: 01_ΕΡΓΑΣΤΗΡΙΟ!B10 | F9: .
A10: 5 | B10: 1. Μέτρα θέσης/διασποράς | C10: Υπολόγισε 1ο & 3ο τεταρτημόριο (QUARTILE.INC) και IQR για το δείγμα 25 προϊόντων (tbl_ProductsView). | D10: products | E10: 01_ΕΡΓΑΣΤΗΡΙΟ!B11:B13 | F10: .
A11: 6 | B11: 2. Καθαρισμός δεδομένων (Text) | C11: 2.1 Με MID+FIND+LEN εξήγαγε την πόλη από κείμενο τύπου "City: Londona" (πάρε ό,τι είναι μετά το ": "). | D11: suppliers | E11: 01_ΕΡΓΑΣΤΗΡΙΟ!G7 | F11: .
A12: 7 | B12: 2. Καθαρισμός δεδομένων (Text) | C12: 2.2 Με FIND+MID+LEN+CONCAT αφαίρεσε παρενθέσεις/παύλα από το Phone και εμφάνισε το ως "171 5552222". | D12: suppliers | E12: 01_ΕΡΓΑΣΤΗΡΙΟ!G8 | F12: .
A13: 8 | B13: 2. Καθαρισμός δεδομένων (Text) | C13: 2.3 Με LEFT/RIGHT/FIND/LEN/CONCAT χώρισε το "Contact|Supplier" και σύνθεσε το ως "Contact (Supplier)". | D13: suppliers | E13: 01_ΕΡΓΑΣΤΗΡΙΟ!G9 | F13: .
A14: 9 | B14: 2. Καθαρισμός δεδομένων (Text) | C14: Εξήγαγε το πρώτο μέρος της διεύθυνσης (μέχρι το πρώτο κόμμα) με LEFT + FIND. | D14: customers | E14: 01_ΕΡΓΑΣΤΗΡΙΟ!G10 | F14: .
A15: 10 | B15: 3. Μορφοποίηση υπό όρους | C15: Τόνισε προϊόντα με Price>50 με κόκκινο γέμισμα | D15: products | E15: 01_ΕΡΓΑΣΤΗΡΙΟ!A52:G77 | F15: .
A16: 11 | B16: 3. Μορφοποίηση υπό όρους | C16: Εφάρμοσε Icon Set (3 traffic lights) στη στήλη Quantity (orderdetails). | D16: orderdetails | E16: 01_ΕΡΓΑΣΤΗΡΙΟ!L52:L77 | F16: ,
A17: 12 | B17: 4. Πίνακες & δυναμικά φίλτρα | C17: Χρησιμοποίησε COUNTIF για να βρεις πόσα προϊόντα του δείγματος (tbl_ProductsView, σας έχω βάλει στο κάτω μέρος του φύλλου 01_ΕΡΓΑΣΤΗΡΙΟ τον πίνακα που θα χρησιμοποιήσετε) ανήκουν στο CategoryName που επιλέγεις (B20). (Προαιρετικά: φιλτράρισε τον πίνακα για οπτικό έλεγχο) | D17: products+categories | E17: 01_ΕΡΓΑΣΤΗΡΙΟ!B22 | F17: .
... A32: 27 | B32: 7. MAXIFS/MINIFS | C32: Με MINIFS: ελάχιστη τιμή προϊόντος ανά SupplierID=12. | D32: products | E32: 01_ΕΡΓΑΣΤΗΡΙΟ!B46 | F32: .
A33: 28 | B33: 8. PivotTables | C33: Pivot 1: Σύνολο Πωλήσεων ανά Category (SalesValue). | D33: 03_PIVOT | E33: 03_PIVOT!A5
A34: 29 | B34: 8. PivotTables | C34: Pivot 2: Ανάλυση συχνότητας — Πλήθος Orders ανά Country. | D34: 03_PIVOT | E34: 03_PIVOT!A18
A35: 30 | B35: 8. PivotTables | C35: Εφάρμοσε Slicer για CategoryName και φίλτρο ημερομηνίας (με PivotDateFilter). | D35: 03_PIVOT | E35: 03_PIVOT (slicers δεξιά)
A36: 31 | B36: 8. PivotTables | C36: Pivot 1b: Εμφάνιση τιμών ως % Column Total (Show Values As). | D36: 03_PIVOT | E36: 03_PIVOT!D18
A37: 32 | B37: 8. PivotTables | C37: Pivot 3: Ανάλυση συχνότητας ανά κλάση ποσότητας (QtyBand). | D37: 03_PIVOT | E37: 03_PIVOT!A43

Sheet 01_ΕΡΓΑΣΤΗΡΙΟ
A1: Northwind
A5: 1) 📊 Μέτρα θέσης & διασποράς (Price από Πίνακας7) | E5: 2) 🧽 Καθαρισμός δεδομένων (Text functions)
B6: Μαθητής | E6: Πεδίο (raw) | F6: Raw τιμή | G6: Μαθητής | H6: Σχόλιο
A7: Μέσος όρος (AVERAGE) | B7: =AVERAGE(tbl_ProductsView[Price]) -> 27.4 | E7: City (από suppliers) | F7: City: Londona | G7: =MID(F7,FIND(":",F7)+2,LEN(F7)-FIND(":",F7)-1) -> Londona | H7: ← λύση
A8: Διάμεσος (MEDIAN) | B8: =MEDIAN(tbl_ProductsView[[#All],[Price]]) -> 21 | E8: Phone (από suppliers) | F8: =INDEX(Πίνακας9[Phone],1) -> (171) 555-2222 | G8: =_xlfn.CONCAT(MID(F8,FIND("(",F8)+1,FIND(")",F8)-FIND("(",F8)-1)," ",MID(F8,FIND(")",F8)+2,FIND("-",F8)-FIND(")",F8)-2),MID(F8,FIND("-",F8)+1,LEN(F8)-FIND("-",F8))) -> 171 5552222 | H8: ← λύση
A9: Επικρατούσα τιμή (MODE.SNGL) | B9: =_xlfn.MODE.SNGL(tbl_ProductsView[[#All],[Price]]) -> 21 | E9: Contact (Supplier) | F9: Charlotte Cooper|Exotic Liquid | G9: =_xlfn.CONCAT(LEFT(F9,LEN(F9)-FIND("|",F9)+3)," ","(",RIGHT(F9,LEN(F9)-FIND("|",F9)),")") -> Charlotte Cooper (Exotic Liquid) | H9: ← λύση
A10: Τυπική απόκλιση (STDEV.S) | B10: =_xlfn.STDEV.S(tbl_ProductsView[[#All],[Price]]) -> 22.735801 | E10: Address (από customers!D8) | F10: =customers!D8 -> 24, place Kleber | G10: =LEFT(F10,FIND(",",F10)-1) -> 24 | H10: ← λύση
A11: Q1 (QUARTILE.INC,1) | B11: =_xlfn.QUARTILE.INC(tbl_ProductsView[[#All],[Price]],1) -> 14
A12: Q3 (QUARTILE.INC,3) | B12: =_xlfn.QUARTILE.INC(tbl_ProductsView[[#All],[Price]],3) -> 31
A13: IQR (Q3-Q1) | B13: =(B12-B11) -> 17
E17: 4β) 🌍 COUNTIF — Πλήθος πελατών ανά χώρα (χωρίς UNIQUE/SORT)
A18: 4) 🧮 Πίνακες & Δυναμικά φίλτρα | E18: Χώρα | F18: Μαθητής
A19: Επιλογή CategoryName | B19: Μαθητής | E19: UK | F19: =COUNTIF(Πίνακας1[[#All],[Country]],"UK") -> 7
A20: CategoryName (drop-down): | B20: Beverages | E20: USA | F20: =COUNTIF(Πίνακας1[[#All],[Country]],"USA") -> 13
A21: Φίλτρο πίνακα: Εμφάνισε προϊόντα του CategoryName που διάλεξες (B20) | E21: Germany | F21: =COUNTIF(Πίνακας1[[#All],[Country]],"Germany") -> 11
A22: Πλήθος προϊόντων στο δείγμα (COUNTIF) → | B22: =COUNTIF(tbl_ProductsView[[#All],[CategoryName]],"Beverages") -> 3 | E22: France | F22: =COUNTIF(Πίνακας1[[#All],[Country]],"France") -> 11
A24: 5) 🔎 VLOOKUP / XLOOKUP / HLOOKUP | E24: Βοηθητικός πίνακας (TRANSPOSE) για HLOOKUP:
A25: Παράμετρος | B25: Μαθητής | C25: Σχόλιο | E25: Μικρός οριζόντιος πίνακας (για HLOOKUP)
A26: ProductID: | B26: 3 | E26: 1 | F26: 2 | G26: 3 | H26: 4 | I26: 5
A27: VLOOKUP → ProductName | B27: =VLOOKUP(B26,tbl_ProductsView[#All],2,FALSE) -> Aniseed Syrup | C27: Χρησιμοποιήστε το B26 ως ProductID(τιμή αναζήτησης) | E27: 18 | F27: 19 | G27: 10 | H27: 22 | I27: 21
A28: XLOOKUP → Price | B28: {=_xlfn.XLOOKUP(B26,tbl_ProductsView[[#All],[ProductID]],tbl_ProductsView[[#All],[Price]])} -> 10 | C28: Χρησιμοποιήστε το B26 ως ProductID(τιμή αναζήτησης)
A29: HLOOKUP → Price (οριζόντιος πίνακας) | B29: =HLOOKUP(B26,E26:I27,2,FALSE) -> 10 | C29: Χρησιμοποιήστε το B26 ως ProductID(τιμή αναζήτησης)
A31: 6) ✅ IF / Nested IF / AND / OR / NOT
A32: Ζητούμενο | B32: Μαθητής | C32: Input
A33: IF (Αν τιμή <20 → "Low" αλλιώς "OK") | B33: =IF(C33<20,"Low","OK") -> Low | C33: 15
A34: Nested IF (Low/Medium/High με βάση τιμή) | B34: {=_xlfn.IFS(C33<20,"Low",C33<=50,"Medium",C33>50,"High")} -> Low
A35: IF + AND (αν D35="Yes" ΚΑΙ E35="Yes") | C35: Yes
A36: IF + OR (αν χώρα USA ή UK) | B36: =IF(OR(C36="UK",C36="USA"),"Yes","No") -> Yes | C36: USA
A37: IF + NOT (αν ΔΕΝ είναι Germany) | B37: =IF(NOT(C37="Germany"),"OK","Germany") -> Germany | C37: Germany
A39: 7) ➕ SUMIF / SUMIFS / COUNTIF / AVERAGEIF / MAXIFS / MINIFS
A40: Ζητούμενο | B40: Μαθητής | C40: Input
A41: SUMIF Quantity για ProductID | B41: =SUMIF(Πίνακας2[[#All],[ProductID]],11,Πίνακας2[[#All],[Quantity]]) -> 182 | C41: 11
A42: COUNTIF customers από UK | B42: =COUNTIF(Πίνακας1[[#All],[Country]],"UK") -> 7
A43: AVERAGEIF Price για CategoryID | B43: =AVERAGEIF(Πίνακας7[[#All],[CategoryID]],1,Πίνακας7[[#All],[Price]]) -> 38.083333 | C43: 1
A44: SUMIFS SalesValue για Country | B44: =SUMIFS(tbl_FACTS[[#All],[SalesValue]],tbl_FACTS[[#All],[Country]],"USA") -> 69722 | C44: USA
A45: MAXIFS Price για SupplierID | B45: =_xlfn.MAXIFS(Πίνακας7[[#All],[Price]],Πίνακας7[[#All],[SupplierID]],12) -> 124 | C45: 12
A46: MINIFS Price για SupplierID | B46: =_xlfn.MINIFS(Πίνακας7[[#All],[Price]],Πίνακας7[[#All],[SupplierID]],12) -> 8 | C46: 12
A50: 📋 tbl_ProductsView — Πίνακας προϊόντων για φίλτρα (από φύλλο products)
A52: ProductID | B52: ProductName | C52: SupplierID | D52: CategoryID | E52: Unit | F52: Price | G52: CategoryName | I52: OrderDetailID | J52: OrderID | K52: ProductID | L52: Quantity
A53: 1 | B53: Chais | C53: 1 | D53: 1 | E53: 10 boxes x 20 bags | F53: 18 | G53: =VLOOKUP(tbl_ProductsView[[#This Row],[CategoryID]],categories!$A:$B,2,FALSE) -> Beverages | I53: 1 | J53: 10248 | K53: 11 | L53: 12
...

Sheet 02_FACTS
A1: OrderDetailID | B1: OrderID | C1: ProductID | D1: Quantity | E1: OrderDate | F1: CustomerID | G1: CustomerName | H1: Country | I1: EmployeeID | J1: ShipperID | K1: ShipperName | L1: ProductName | M1: CategoryID | N1: CategoryName | O1: SupplierID | P1: SupplierName | Q1: Price | R1: SalesValue | S1: IsFirstLine | T1: Year | U1: Month | V1: QtyBand
A2: 1 | B2: 10248 | C2: 11 | D2: 12 | E2: =_xlfn.XLOOKUP(tbl_FACTS[[#This Row],[OrderID]],Πίνακας64[OrderID],Πίνακας64[OrderDate]) -> 35250 | F2: =_xlfn.XLOOKUP(tbl_FACTS[[#This Row],[OrderID]],Πίνακας64[OrderID],Πίνακας64[CustomerID]) -> 90 | G2: =_xlfn.XLOOKUP(tbl_FACTS[[#This Row],[CustomerID]],Πίνακας1[CustomerID],Πίνακας1[CustomerName]) -> Wilman Kala | H2: =_xlfn.XLOOKUP(tbl_FACTS[[#This Row],[CustomerID]],Πίνακας1[CustomerID],Πίνακας1[Country]) -> Finland | I2: =_xlfn.XLOOKUP(tbl_FACTS[[#This Row],[OrderID]],Πίνακας64[OrderID],Πίνακας64[EmployeeID]) -> 5 | J2: =_xlfn.XLOOKUP(tbl_FACTS[[#This Row],[OrderID]],Πίνακας64[OrderID],Πίνακας64[ShipperID]) -> 3 | K2: =_xlfn.XLOOKUP(tbl_FACTS[[#This Row],[ShipperID]],Πίνακας8[ShipperID],Πίνακας8[ShipperName]) -> Federal Shipping | L2: =_xlfn.XLOOKUP(tbl_FACTS[[#This Row],[ProductID]],Πίνακας7[ProductID],Πίνακας7[ProductName]) -> Queso Cabrales | M2: =_xlfn.XLOOKUP(tbl_FACTS[[#This Row],[ProductID]],Πίνακας7[ProductID],Πίνακας7[CategoryID]) -> 4 | N2: =_xlfn.XLOOKUP(tbl_FACTS[[#This Row],[CategoryID]],Πίνακας4[CategoryID],Πίνακας4[CategoryName]) -> Dairy Products | O2: =_xlfn.XLOOKUP(tbl_FACTS[[#This Row],[ProductID]],Πίνακας7[ProductID],Πίνακας7[SupplierID]) -> 5 | P2: =_xlfn.XLOOKUP(tbl_FACTS[[#This Row],[SupplierID]],Πίνακας9[SupplierID],Πίνακας9[SupplierName]) -> Cooperativa de Quesos 'Las Cabras' | Q2: =_xlfn.XLOOKUP(tbl_FACTS[[#This Row],[ProductID]],Πίνακας7[ProductID],Πίνακας7[Price]) -> 21 | R2: =tbl_FACTS[[#This Row],[Quantity]]*tbl_FACTS[[#This Row],[Price]] -> 252 | S2: =IF(COUNTIFS(tbl_FACTS[OrderID],tbl_FACTS[[#This Row],[OrderID]],tbl_FACTS[OrderDetailID],"<"&tbl_FACTS[[#This Row],[OrderDetailID]])=0,1,0) -> 1 | T2: =YEAR(tbl_FACTS[[#This Row],[OrderDate]]) -> 1996 | U2: =DATE(YEAR(tbl_FACTS[[#This Row],[OrderDate]]),MONTH(tbl_FACTS[[#This Row],[OrderDate]]),1) -> 35247 | V2: =IF(tbl_FACTS[[#This Row],[Quantity]]<=10,"0–10",IF(tbl_FACTS[[#This Row],[Quantity]]<=20,"11–20",IF(tbl_FACTS[[#This Row],[Quantity]]<=30,"21–30",IF(tbl_FACTS[[#This Row],[Quantity]]<=40,"31–40",IF(tbl_FACTS[[#This Row],[Quantity]]<=50,"41–50","51+"))))) -> 11–20
A3: 2 | B3: 10248 | C3: 42 | D3: 10 | E3: =_xlfn.XLOOKUP(tbl_FACTS[[#This Row],[OrderID]],Πίνακας64[OrderID],Πίνακας64[OrderDate]) -> 35250 | F3: =_xlfn.XLOOKUP(tbl_FACTS[[#This Row],[OrderID]],Πίνακας64[OrderID],Πίνακας64[CustomerID]) -> 90 | G3: =_xlfn.XLOOKUP(tbl_FACTS[[#This Row],[CustomerID]],Πίνακας1[CustomerID],Πίνακας1[CustomerName]) -> Wilman Kala | H3: =_xlfn.XLOOKUP(tbl_FACTS[[#This Row],[CustomerID]],Πίνακας1[CustomerID],Πίνακας1[Country]) -> Finland | I3: =_xlfn.XLOOKUP(tbl_FACTS[[#This Row],[OrderID]],Πίνακας64[OrderID],Πίνακας64[EmployeeID]) -> 5 | J3: =_xlfn.XLOOKUP(tbl_FACTS[[#This Row],[OrderID]],Πίνακας64[OrderID],Πίνακας64[ShipperID]) -> 3 | K3: =_xlfn.XLOOKUP(tbl_FACTS[[#This Row],[ShipperID]],Πίνακας8[ShipperID],Πίνακας8[ShipperName]) -> Federal Shipping | L3: =_xlfn.XLOOKUP(tbl_FACTS[[#This Row],[ProductID]],Πίνακας7[ProductID],Πίνακας7[ProductName]) -> Singaporean Hokkien Fried Mee | M3: =_xlfn.XLOOKUP(tbl_FACTS[[#This Row],[ProductID]],Πίνακας7[ProductID],Πίνακας7[CategoryID]) -> 5 | N3: =_xlfn.XLOOKUP(tbl_FACTS[[#This Row],[CategoryID]],Πίνακας4[CategoryID],Πίνακας4[CategoryName]) -> Grains/Cereals | O3: =_xlfn.XLOOKUP(tbl_FACTS[[#This Row],[ProductID]],Πίνακας7[ProductID],Πίνακας7[SupplierID]) -> 20 | P3: =_xlfn.XLOOKUP(tbl_FACTS[[#This Row],[SupplierID]],Πίνακας9[SupplierID],Πίνακας9[SupplierName]) -> Leka Trading | Q3: =_xlfn.XLOOKUP(tbl_FACTS[[#This Row],[ProductID]],Πίνακας7[ProductID],Πίνακας7[Price]) -> 14 | R3: =tbl_FACTS[[#This Row],[Quantity]]*tbl_FACTS[[#This Row],[Price]] -> 140 | S3: =IF(COUNTIFS(tbl_FACTS[OrderID],tbl_FACTS[[#This Row],[OrderID]],tbl_FACTS[OrderDetailID],"<"&tbl_FACTS[[#This Row],[OrderDetailID]])=0,1,0) -> 0 | T3: =YEAR(tbl_FACTS[[#This Row],[OrderDate]]) -> 1996 | U3: =DATE(YEAR(tbl_FACTS[[#This Row],[OrderDate]]),MONTH(tbl_FACTS[[#This Row],[OrderDate]]),1) -> 35247 | V3: =IF(tbl_FACTS[[#This Row],[Quantity]]<=10,"0–10",IF(tbl_FACTS[[#This Row],[Quantity]]<=20,"11–20",IF(tbl_FACTS[[#This Row],[Quantity]]<=30,"21–30",IF(tbl_FACTS[[#This Row],[Quantity]]<=40,"31–40",IF(tbl_FACTS[[#This Row],[Quantity]]<=50,"41–50","51+"))))) -> 0–10
A4: 3 | B4: 10248 | C4: 72 | D4: 5 | E4: =_xlfn.XLOOKUP(tbl_FACTS[[#This Row],[OrderID]],Πίνακας64[OrderID],Πίνακας64[OrderDate]) -> 35250 | F4: =_xlfn.XLOOKUP(tbl_FACTS[[#This Row],[OrderID]],Πίνακας64[OrderID],Πίνακας64[CustomerID]) -> 90 | G4: =_xlfn.XLOOKUP(tbl_FACTS[[#This Row],[CustomerID]],Πίνακας1[CustomerID],Πίνακας1[CustomerName]) -> Wilman Kala | H4: =_xlfn.XLOOKUP(tbl_FACTS[[#This Row],[CustomerID]],Πίνακας1[CustomerID],Πίνακας1[Country]) -> Finland | I4: =_xlfn.XLOOKUP(tbl_FACTS[[#This Row],[OrderID]],Πίνακας64[OrderID],Πίνακας64[EmployeeID]) -> 5 | J4: =_xlfn.XLOOKUP(tbl_FACTS[[#This Row],[OrderID]],Πίνακας64[OrderID],Πίνακας64[ShipperID]) -> 3 | K4: =_xlfn.XLOOKUP(tbl_FACTS[[#This Row],[ShipperID]],Πίνακας8[ShipperID],Πίνακας8[ShipperName]) -> Federal Shipping | L4: =_xlfn.XLOOKUP(tbl_FACTS[[#This Row],[ProductID]],Πίνακας7[ProductID],Πίνακας7[ProductName]) -> Mozzarella di Giovanni | M4: =_xlfn.XLOOKUP(tbl_FACTS[[#This Row],[ProductID]],Πίνακας7[ProductID],Πίνακας7[CategoryID]) -> 4 | N4: =_xlfn.XLOOKUP(tbl_FACTS[[#This Row],[CategoryID]],Πίνακας4[CategoryID],Πίνακας4[CategoryName]) -> Dairy Products | O4: =_xlfn.XLOOKUP(tbl_FACTS[[#This Row],[ProductID]],Πίνακας7[ProductID],Πίνακας7[SupplierID]) -> 14 | P4: =_xlfn.XLOOKUP(tbl_FACTS[[#This Row],[SupplierID]],Πίνακας9[SupplierID],Πίνακας9[SupplierName]) -> Formaggi Fortini s.r.l. | Q4: =_xlfn.XLOOKUP(tbl_FACTS[[#This Row],[ProductID]],Πίνακας7[ProductID],Πίνακας7[Price]) -> 35 | R4: =tbl_FACTS[[#This Row],[Quantity]]*tbl_FACTS[[#This Row],[Price]] -> 175 | S4: =IF(COUNTIFS(tbl_FACTS[OrderID],tbl_FACTS[[#This Row],[OrderID]],tbl_FACTS[OrderDetailID],"<"&tbl_FACTS[[#This Row],[OrderDetailID]])=0,1,0) -> 0 | T4: =YEAR(tbl_FACTS[[#This Row],[OrderDate]]) -> 1996 | U4: =DATE(YEAR(tbl_FACTS[[#This Row],[OrderDate]]),MONTH(tbl_FACTS[[#This Row],[OrderDate]]),1) -> 35247 | V4: =IF(tbl_FACTS[[#This Row],[Quantity]]<=10,"0–10",IF(tbl_FACTS[[#This Row],[Quantity]]<=20,"11–20",IF(tbl_FACTS[[#This Row],[Quantity]]<=30,"21–30",IF(tbl_FACTS[[#This Row],[Quantity]]<=40,"31–40",IF(tbl_FACTS[[#This Row],[Quantity]]<=50,"41–50","51+"))))) -> 0–10
A5: 4 | B5: 10249 | C5: 14 | D5: 9 | E5: =_xlfn.XLOOKUP(tbl_FACTS[[#This Row],[OrderID]],Πίνακας64[OrderID],Πίνακας64[OrderDate]) -> 35251 | F5: =_xlfn.XLOOKUP(tbl_FACTS[[#This Row],[OrderID]],Πίνακας64[OrderID],Πίνακας64[CustomerID]) -> 81 | G5: =_xlfn.XLOOKUP(tbl_FACTS[[#This Row],[CustomerID]],Πίνακας1[CustomerID],Πίνακας1[CustomerName]) -> Tradicao Hipermercados | H5: =_xlfn.XLOOKUP(tbl_FACTS[[#This Row],[CustomerID]],Πίνακας1[CustomerID],Πίνακας1[Country]) -> Brazil | I5: =_xlfn.XLOOKUP(tbl_FACTS[[#This Row],[OrderID]],Πίνακας64[OrderID],Πίνακας64[EmployeeID]) -> 6 | J5: =_xlfn.XLOOKUP(tbl_FACTS[[#This Row],[OrderID]],Πίνακας64[OrderID],Πίνακας64[ShipperID]) -> 1 | K5: =_xlfn.XLOOKUP(tbl_FACTS[[#This Row],[ShipperID]],Πίνακας8[ShipperID],Πίνακας8[ShipperName]) -> Speedy Express | L5: =_xlfn.XLOOKUP(tbl_FACTS[[#This Row],[ProductID]],Πίνακας7[ProductID],Πίνακας7[ProductName]) -> Tofu | M5: =_xlfn.XLOOKUP(tbl_FACTS[[#This Row],[ProductID]],Πίνακας7[ProductID],Πίνακας7[CategoryID]) -> 7 | N5: =_xlfn.XLOOKUP(tbl_FACTS[[#This Row],[CategoryID]],Πίνακας4[CategoryID],Πίνακας4[CategoryName]) -> Produce | O5: =_xlfn.XLOOKUP(tbl_FACTS[[#This Row],[ProductID]],Πίνακας7[ProductID],Πίνακας7[SupplierID]) -> 6 | P5: =_xlfn.XLOOKUP(tbl_FACTS[[#This Row],[SupplierID]],Πίνακας9[SupplierID],Πίνακας9[SupplierName]) -> Mayumi's | Q5: =_xlfn.XLOOKUP(tbl_FACTS[[#This Row],[ProductID]],Πίνακας7[ProductID],Πίνακας7[Price]) -> 23 | R5: =tbl_FACTS[[#This Row],[Quantity]]*tbl_FACTS[[#This Row],[Price]] -> 207 | S5: =IF(COUNTIFS(tbl_FACTS[OrderID],tbl_FACTS[[#This Row],[OrderID]],tbl_FACTS[OrderDetailID],"<"&tbl_FACTS[[#This Row],[OrderDetailID]])=0,1,0) -> 1 | T5: =YEAR(tbl_FACTS[[#This Row],[OrderDate]]) -> 1996 | U5: =DATE(YEAR(tbl_FACTS[[#This Row],[OrderDate]]),MONTH(tbl_FACTS[[#This Row],[OrderDate]]),1) -> 35247 | V5: =IF(tbl_FACTS[[#This Row],[Quantity]]<=10,"0–10",IF(tbl_FACTS[[#This Row],[Quantity]]<=20,"11–20",IF(tbl_FACTS[[#This Row],[Quantity]]<=30,"21–30",IF(tbl_FACTS[[#This Row],[Quantity]]<=40,"31–40",IF(tbl_FACTS[[#This Row],[Quantity]]<=50,"41–50","51+"))))) -> 0–10
A6: 5 | B6: 10249 | C6: 51 | D6: 40 | E6: =_xlfn.XLOOKUP(tbl_FACTS[[#This Row],[OrderID]],Πίνακας64[OrderID],Πίνακας64[OrderDate]) -> 35251 | F6: =_xlfn.XLOOKUP(tbl_FACTS[[#This Row],[OrderID]],Πίνακας64[OrderID],Πίνακας64[CustomerID]) -> 81 | G6: =_xlfn.XLOOKUP(tbl_FACTS[[#This Row],[CustomerID]],Πίνακας1[CustomerID],Πίνακας1[CustomerName]) -> Tradicao Hipermercados | H6: =_xlfn.XLOOKUP(tbl_FACTS[[#This Row],[CustomerID]],Πίνακας1[CustomerID],Πίνακας1[Country]) -> Brazil | I6: =_xlfn.XLOOKUP(tbl_FACTS[[#This Row],[OrderID]],Πίνακας64[OrderID],Πίνακας64[EmployeeID]) -> 6 | J6: =_xlfn.XLOOKUP(tbl_FACTS[[#This Row],[OrderID]],Πίνακας64[OrderID],Πίνακας64[ShipperID]) -> 1 | K6: =_xlfn.XLOOKUP(tbl_FACTS[[#This Row],[ShipperID]],Πίνακας8[ShipperID],Πίνακας8[ShipperName]) -> Speedy Express | L6: =_xlfn.XLOOKUP(tbl_FACTS[[#This Row],[ProductID]],Πίνακας7[ProductID],Πίνακας7[ProductName]) -> Manjimup Dried Apples | M6: =_xlfn.XLOOKUP(tbl_FACTS[[#This Row],[ProductID]],Πίνακας7[ProductID],Πίνακας7[CategoryID]) -> 7 | N6: =_xlfn.XLOOKUP(tbl_FACTS[[#This Row],[CategoryID]],Πίνακας4[CategoryID],Πίνακας4[CategoryName]) -> Produce | O6: =_xlfn.XLOOKUP(tbl_FACTS[[#This Row],[ProductID]],Πίνακας7[ProductID],Πίνακας7[SupplierID]) -> 24 | P6: =_xlfn.XLOOKUP(tbl_FACTS[[#This Row],[SupplierID]],Πίνακας9[SupplierID],Πίνακας9[SupplierName]) -> G'day, Mate | Q6: =_xlfn.XLOOKUP(tbl_FACTS[[#This Row],[ProductID]],Πίνακας7[ProductID],Πίνακας7[Price]) -> 53 | R6: =tbl_FACTS[[#This Row],[Quantity]]*tbl_FACTS[[#This Row],[Price]] -> 2120 | S6: =IF(COUNTIFS(tbl_FACTS[OrderID],tbl_FACTS[[#This Row],[OrderID]],tbl_FACTS[OrderDetailID],"<"&tbl_FACTS[[#This Row],[OrderDetailID]])=0,1,0) -> 0 | T6: =YEAR(tbl_FACTS[[#This Row],[OrderDate]]) -> 1996 | U6: =DATE(YEAR(tbl_FACTS[[#This Row],[OrderDate]]),MONTH(tbl_FACTS[[#This Row],[OrderDate]]),1) -> 35247 | V6: =IF(tbl_FACTS[[#This Row],[Quantity]]<=10,"0–10",IF(tbl_FACTS[[#This Row],[Quantity]]<=20,"11–20",IF(tbl_FACTS[[#This Row],[Quantity]]<=30,"21–30",IF(tbl_FACTS[[#This Row],[Quantity]]<=40,"31–40",IF(tbl_FACTS[[#This Row],[Quantity]]<=50,"41–50","51+"))))) -> 31–40
A7: 6 | B7: 10250 | C7: 41 | D7: 10 | E7: =_xlfn.XLOOKUP(tbl_FACTS[[#This Row],[OrderID]],Πίνακας64[OrderID],Πίνακας64[OrderDate]) -> 35254 | F7: =_xlfn.XLOOKUP(tbl_FACTS[[#This Row],[OrderID]],Πίνακας64[OrderID],Πίνακας64[CustomerID]) -> 34 | G7: =_xlfn.XLOOKUP(tbl_FACTS[[#This Row],[CustomerID]],Πίνακας1[CustomerID],Πίνακας1[CustomerName]) -> Hanari Carnes | H7: =_xlfn.XLOOKUP(tbl_FACTS[[#This Row],[CustomerID]],Πίνακας1[CustomerID],Πίνακας1[Country]) -> Brazil | I7: =_xlfn.XLOOKUP(tbl_FACTS[[#This Row],[OrderID]],Πίνακας64[OrderID],Πίνακας64[EmployeeID]) -> 4 | J7: =_xlfn.XLOOKUP(tbl_FACTS[[#This Row],[OrderID]],Πίνακας64[OrderID],Πίνακας64[ShipperID]) -> 2 | K7: =_xlfn.XLOOKUP(tbl_FACTS[[#This Row],[ShipperID]],Πίνακας8[ShipperID],Πίνακας8[ShipperName]) -> United Package | L7: =_xlfn.XLOOKUP(tbl_FACTS[[#This Row],[ProductID]],Πίνακας7[ProductID],Πίνακας7[ProductName]) -> Jack's New England Clam Chowder | M7: =_xlfn.XLOOKUP(tbl_FACTS[[#This Row],[ProductID]],Πίνακας7[ProductID],Πίνακας7[CategoryID]) -> 8 | N7: =_xlfn.XLOOKUP(tbl_FACTS[[#This Row],[CategoryID]],Πίνακας4[CategoryID],Πίνακας4[CategoryName]) -> Seafood | O7: =_xlfn.XLOOKUP(tbl_FACTS[[#This Row],[ProductID]],Πίνακας7[ProductID],Πίνακας7[SupplierID]) -> 19 | P7: =_xlfn.XLOOKUP(tbl_FACTS[[#This Row],[SupplierID]],Πίνακας9[SupplierID],Πίνακας9[SupplierName]) -> New England Seafood Cannery | Q7: =_xlfn.XLOOKUP(tbl_FACTS[[#This Row],[ProductID]],Πίνακας7[ProductID],Πίνακας7[Price]) -> 10 | R7: =tbl_FACTS[[#This Row],[Quantity]]*tbl_FACTS[[#This Row],[Price]] -> 100 | S7: =IF(COUNTIFS(tbl_FACTS[OrderID],tbl_FACTS[[#This Row],[OrderID]],tbl_FACTS[OrderDetailID],"<"&tbl_FACTS[[#This Row],[OrderDetailID]])=0,1,0) -> 1 | T7: =YEAR(tbl_FACTS[[#This Row],[OrderDate]]) -> 1996 | U7: =DATE(YEAR(tbl_FACTS[[#This Row],[OrderDate]]),MONTH(tbl_FACTS[[#This Row],[OrderDate]]),1) -> 35247 | V7: =IF(tbl_FACTS[[#This Row],[Quantity]]<=10,"0–10",IF(tbl_FACTS[[#This Row],[Quantity]]<=20,"11–20",IF(tbl_FACTS[[#This Row],[Quantity]]<=30,"21–30",IF(tbl_FACTS[[#This Row],[Quantity]]<=40,"31–40",IF(tbl_FACTS[[#This Row],[Quantity]]<=50,"41–50","51+"))))) -> 0–10
A8: 7 | B8: 10250 | C8: 51 | D8: 35 | E8: =_xlfn.XLOOKUP(tbl_FACTS[[#This Row],[OrderID]],Πίνακας64[OrderID],Πίνακας64[OrderDate]) -> 35254 | F8: =_xlfn.XLOOKUP(tbl_FACTS[[#This Row],[OrderID]],Πίνακας64[OrderID],Πίνακας64[CustomerID]) -> 34 | G8: =_xlfn.XLOOKUP(tbl_FACTS[[#This Row],[CustomerID]],Πίνακας1[CustomerID],Πίνακας1[CustomerName]) -> Hanari Carnes | H8: =_xlfn.XLOOKUP(tbl_FACTS[[#This Row],[CustomerID]],Πίνακας1[CustomerID],Πίνακας1[Country]) -> Brazil | I8: =_xlfn.XLOOKUP(tbl_FACTS[[#This Row],[OrderID]],Πίνακας64[OrderID],Πίνακας64[EmployeeID]) -> 4 | J8: =_xlfn.XLOOKUP(tbl_FACTS[[#This Row],[OrderID]],Πίνακας64[OrderID],Πίνακας64[ShipperID]) -> 2 | K8: =_xlfn.XLOOKUP(tbl_FACTS[[#This Row],[ShipperID]],Πίνακας8[ShipperID],Πίνακας8[ShipperName]) -> United Package | L8: =_xlfn.XLOOKUP(tbl_FACTS[[#This Row],[ProductID]],Πίνακας7[ProductID],Πίνακας7[ProductName]) -> Manjimup Dried Apples | M8: =_xlfn.XLOOKUP(tbl_FACTS[[#This Row],[ProductID]],Πίνακας7[ProductID],Πίνακας7[CategoryID]) -> 7 | N8: =_xlfn.XLOOKUP(tbl_FACTS[[#This Row],[CategoryID]],Πίνακας4[CategoryID],Πίνακας4[CategoryName]) -> Produce | O8: =_xlfn.XLOOKUP(tbl_FACTS[[#This Row],[ProductID]],Πίνακας7[ProductID],Πίνακας7[SupplierID]) -> 24 | P8: =_xlfn.XLOOKUP(tbl_FACTS[[#This Row],[SupplierID]],Πίνακας9[SupplierID],Πίνακας9[SupplierName]) -> G'day, Mate | Q8: =_xlfn.XLOOKUP(tbl_FACTS[[#This Row],[ProductID]],Πίνακας7[ProductID],Πίνακας7[Price]) -> 53 | R8: =tbl_FACTS[[#This Row],[Quantity]]*tbl_FACTS[[#This Row],[Price]] -> 1855 | S8: =IF(COUNTIFS(tbl_FACTS[OrderID],tbl_FACTS[[#This Row],[OrderID]],tbl_FACTS[OrderDetailID],"<"&tbl_FACTS[[#This Row],[OrderDetailID]])=0,1,0) -> 0 | T8: =YEAR(tbl_FACTS[[#This Row],[OrderDate]]) -> 1996 | U8: =DATE(YEAR(tbl_FACTS[[#This Row],[OrderDate]]),MONTH(tbl_FACTS[[#This Row],[OrderDate]]),1) -> 35247 | V8: =IF(tbl_FACTS[[#This Row],[Quantity]]<=10,"0–10",IF(tbl_FACTS[[#This Row],[Quantity]]<=20,"11–20",IF(tbl_FACTS[[#This Row],[Quantity]]<=30,"21–30",IF(tbl_FACTS[[#This Row],[Quantity]]<=40,"31–40",IF(tbl_FACTS[[#This Row],[Quantity]]<=50,"41–50","51+"))))) -> 31–40
A9: 8 | B9: 10250 | C9: 65 | D9: 15 | E9: =_xlfn.XLOOKUP(tbl_FACTS[[#This Row],[OrderID]],Πίνακας64[OrderID],Πίνακας64[OrderDate]) -> 35254 | F9: =_xlfn.XLOOKUP(tbl_FACTS[[#This Row],[OrderID]],Πίνακας64[OrderID],Πίνακας64[CustomerID]) -> 34 | G9: =_xlfn.XLOOKUP(tbl_FACTS[[#This Row],[CustomerID]],Πίνακας1[CustomerID],Πίνακας1[CustomerName]) -> Hanari Carnes | H9: =_xlfn.XLOOKUP(tbl_FACTS[[#This Row],[CustomerID]],Πίνακας1[CustomerID],Πίνακας1[Country]) -> Brazil | I9: =_xlfn.XLOOKUP(tbl_FACTS[[#This Row],[OrderID]],Πίνακας64[OrderID],Πίνακας64[EmployeeID]) -> 4 | J9: =_xlfn.XLOOKUP(tbl_FACTS[[#This Row],[OrderID]],Πίνακας64[OrderID],Πίνακας64[ShipperID]) -> 2 | K9: =_xlfn.XLOOKUP(tbl_FACTS[[#This Row],[ShipperID]],Πίνακας8[ShipperID],Πίνακας8[ShipperName]) -> United Package | L9: =_xlfn.XLOOKUP(tbl_FACTS[[#This Row],[ProductID]],Πίνακας7[ProductID],Πίνακας7[ProductName]) -> Louisiana Fiery Hot Pepper Sauce | M9: =_xlfn.XLOOKUP(tbl_FACTS[[#This Row],[ProductID]],Πίνακας7[ProductID],Πίνακας7[CategoryID]) -> 2 | N9: =_xlfn.XLOOKUP(tbl_FACTS[[#This Row],[CategoryID]],Πίνακας4[CategoryID],Πίνακας4[CategoryName]) -> Condiments | O9: =_xlfn.XLOOKUP(tbl_FACTS[[#This Row],[ProductID]],Πίνακας7[ProductID],Πίνακας7[SupplierID]) -> 2 | P9: =_xlfn.XLOOKUP(tbl_FACTS[[#This Row],[SupplierID]],Πίνακας9[SupplierID],Πίνακας9[SupplierName]) -> New Orleans Cajun Delights | Q9: =_xlfn.XLOOKUP(tbl_FACTS[[#This Row],[ProductID]],Πίνακας7[ProductID],Πίνακας7[Price]) -> 21 | R9: =tbl_FACTS[[#This Row],[Quantity]]*tbl_FACTS[[#This Row],[Price]] -> 315 | S9: =IF(COUNTIFS(tbl_FACTS[OrderID],tbl_FACTS[[#This Row],[OrderID]],tbl_FACTS[OrderDetailID],"<"&tbl_FACTS[[#This Row],[OrderDetailID]])=0,1,0) -> 0 | T9: =YEAR(tbl_FACTS[[#This Row],[OrderDate]]) -> 1996 | U9: =DATE(YEAR(tbl_FACTS[[#This Row],[OrderDate]]),MONTH(tbl_FACTS[[#This Row],[OrderDate]]),1) -> 35247 | V9: =IF(tbl_FACTS[[#This Row],[Quantity]]<=10,"0–10",IF(tbl_FACTS[[#This Row],[Quantity]]<=20,"11–20",IF(tbl_FACTS[[#This Row],[Quantity]]<=30,"21–30",IF(tbl_FACTS[[#This Row],[Quantity]]<=40,"31–40",IF(tbl_FACTS[[#This Row],[Quantity]]<=50,"41–50","51+"))))) -> 11–20
A10: 9 | B10: 10251 | C10: 22 | D10: 6 | E10: =_xlfn.XLOOKUP(tbl_FACTS[[#This Row],[OrderID]],Πίνακας64[OrderID],Πίνακας64[OrderDate]) -> 35254 | F10: =_xlfn.XLOOKUP(tbl_FACTS[[#This Row],[OrderID]],Πίνακας64[OrderID],Πίνακας64[CustomerID]) -> 84 | G10: =_xlfn.XLOOKUP(tbl_FACTS[[#This Row],[CustomerID]],Πίνακας1[CustomerID],Πίνακας1[CustomerName]) -> Victuailles en stock | H10: =_xlfn.XLOOKUP(tbl_FACTS[[#This Row],[CustomerID]],Πίνακας1[CustomerID],Πίνακας1[Country]) -> France | I10: =_xlfn.XLOOKUP(tbl_FACTS[[#This Row],[OrderID]],Πίνακας64[OrderID],Πίνακας64[EmployeeID]) -> 3 | J10: =_xlfn.XLOOKUP(tbl_FACTS[[#This Row],[OrderID]],Πίνακας64[OrderID],Πίνακας64[ShipperID]) -> 1 | K10: =_xlfn.XLOOKUP(tbl_FACTS[[#This Row],[ShipperID]],Πίνακας8[ShipperID],Πίνακας8[ShipperName]) -> Speedy Express | L10: =_xlfn.XLOOKUP(tbl_FACTS[[#This Row],[ProductID]],Πίνακας7[ProductID],Πίνακας7[ProductName]) -> Gustaf's Knackebrod | M10: =_xlfn.XLOOKUP(tbl_FACTS[[#This Row],[ProductID]],Πίνακας7[ProductID],Πίνακας7[CategoryID]) -> 5 | N10: =_xlfn.XLOOKUP(tbl_FACTS[[#This Row],[CategoryID]],Πίνακας4[CategoryID],Πίνακας4[CategoryName]) -> Grains/Cereals | O10: =_xlfn.XLOOKUP(tbl_FACTS[[#This Row],[ProductID]],Πίνακας7[ProductID],Πίνακας7[SupplierID]) -> 9 | P10: =_xlfn.XLOOKUP(tbl_FACTS[[#This Row],[SupplierID]],Πίνακας9[SupplierID],Πίνακας9[SupplierName]) -> PB Knackebrod AB | Q10: =_xlfn.XLOOKUP(tbl_FACTS[[#This Row],[ProductID]],Πίνακας7[ProductID],Πίνακας7[Price]) -> 21 | R10: =tbl_FACTS[[#This Row],[Quantity]]*tbl_FACTS[[#This Row],[Price]] -> 126 | S10: =IF(COUNTIFS(tbl_FACTS[OrderID],tbl_FACTS[[#This Row],[OrderID]],tbl_FACTS[OrderDetailID],"<"&tbl_FACTS[[#This Row],[OrderDetailID]])=0,1,0) -> 1 | T10: =YEAR(tbl_FACTS[[#This Row],[OrderDate]]) -> 1996 | U10: =DATE(YEAR(tbl_FACTS[[#This Row],[OrderDate]]),MONTH(tbl_FACTS[[#This Row],[OrderDate]]),1) -> 35247 | V10: =IF(tbl_FACTS[[#This Row],[Quantity]]<=10,"0–10",IF(tbl_FACTS[[#This Row],[Quantity]]<=20,"11–20",IF(tbl_FACTS[[#This Row],[Quantity]]<=30,"21–30",IF(tbl_FACTS[[#This Row],[Quantity]]<=40,"31–40",IF(tbl_FACTS[[#This Row],[Quantity]]<=50,"41–50","51+"))))) -> 0–10
A11: 10 | B11: 10251 | C11: 57 | D11: 15 | E11: =_xlfn.XLOOKUP(tbl_FACTS[[#This Row],[OrderID]],Πίνακας64[OrderID],Πίνακας64[OrderDate]) -> 35254 | F11: =_xlfn.XLOOKUP(tbl_FACTS[[#This Row],[OrderID]],Πίνακας64[OrderID],Πίνακας64[CustomerID]) -> 84 | G11: =_xlfn.XLOOKUP(tbl_FACTS[[#This Row],[CustomerID]],Πίνακας1[CustomerID],Πίνακας1[CustomerName]) -> Victuailles en stock | H11: =_xlfn.XLOOKUP(tbl_FACTS[[#This Row],[CustomerID]],Πίνακας1[CustomerID],Πίνακας1[Country]) -> France | I11: =_xlfn.XLOOKUP(tbl_FACTS[[#This Row],[OrderID]],Πίνακας64[OrderID],Πίνακας64[EmployeeID]) -> 3 | J11: =_xlfn.XLOOKUP(tbl_FACTS[[#This Row],[OrderID]],Πίνακας64[OrderID],Πίνακας64[ShipperID]) -> 1 | K11: =_xlfn.XLOOKUP(tbl_FACTS[[#This Row],[ShipperID]],Πίνακας8[ShipperID],Πίνακας8[ShipperName]) -> Speedy Express | L11: =_xlfn.XLOOKUP(tbl_FACTS[[#This Row],[ProductID]],Πίνακας7[ProductID],Πίνακας7[ProductName]) -> Ravioli Angelo | M11: =_xlfn.XLOOKUP(tbl_FACTS[[#This Row],[ProductID]],Πίνακας7[ProductID],Πίνακας7[CategoryID]) -> 5 | N11: =_xlfn.XLOOKUP(tbl_FACTS[[#This Row],[CategoryID]],Πίνακας4[CategoryID],Πίνακας4[CategoryName]) -> Grains/Cereals | O11: =_xlfn.XLOOKUP(tbl_FACTS[[#This Row],[ProductID]],Πίνακας7[ProductID],Πίνακας7[SupplierID]) -> 26 | P11: =_xlfn.XLOOKUP(tbl_FACTS[[#This Row],[SupplierID]],Πίνακας9[SupplierID],Πίνακας9[SupplierName]) -> Pasta Buttini s.r.l. | Q11: =_xlfn.XLOOKUP(tbl_FACTS[[#This Row],[ProductID]],Πίνακας7[ProductID],Πίνακας7[Price]) -> 20 | R11: =tbl_FACTS[[#This Row],[Quantity]]*tbl_FACTS[[#This Row],[Price]] -> 300 | S11: =IF(COUNTIFS(tbl_FACTS[OrderID],tbl_FACTS[[#This Row],[OrderID]],tbl_FACTS[OrderDetailID],"<"&tbl_FACTS[[#This Row],[OrderDetailID]])=0,1,0) -> 0 | T11: =YEAR(tbl_FACTS[[#This Row],[OrderDate]]) -> 1996 | U11: =DATE(YEAR(tbl_FACTS[[#This Row],[OrderDate]]),MONTH(tbl_FACTS[[#This Row],[OrderDate]]),1) -> 35247 | V11: =IF(tbl_FACTS[[#This Row],[Quantity]]<=10,"0–10",IF(tbl_FACTS[[#This Row],[Quantity]]<=20,"11–20",IF(tbl_FACTS[[#This Row],[Quantity]]<=30,"21–30",IF(tbl_FACTS[[#This Row],[Quantity]]<=40,"31–40",IF(tbl_FACTS[[#This Row],[Quantity]]<=50,"41–50","51+"))))) -> 11–20
A12: 11 | B12: 10251 | C12: 65 | D12: 20 | E12: =_xlfn.XLOOKUP(tbl_FACTS[[#This Row],[OrderID]],Πίνακας64[OrderID],Πίνακας64[OrderDate]) -> 35254 | F12: =_xlfn.XLOOKUP(tbl_FACTS[[#This Row],[OrderID]],Πίνακας64[OrderID],Πίνακας64[CustomerID]) -> 84 | G12: =_xlfn.XLOOKUP(tbl_FACTS[[#This Row],[CustomerID]],Πίνακας1[CustomerID],Πίνακας1[CustomerName]) -> Victuailles en stock | H12: =_xlfn.XLOOKUP(tbl_FACTS[[#This Row],[CustomerID]],Πίνακας1[CustomerID],Πίνακας1[Country]) -> France | I12: =_xlfn.XLOOKUP(tbl_FACTS[[#This Row],[OrderID]],Πίνακας64[OrderID],Πίνακας64[EmployeeID]) -> 3 | J12: =_xlfn.XLOOKUP(tbl_FACTS[[#This Row],[OrderID]],Πίνακας64[OrderID],Πίνακας64[ShipperID]) -> 1 | K12: =_xlfn.XLOOKUP(tbl_FACTS[[#This Row],[ShipperID]],Πίνακας8[ShipperID],Πίνακας8[ShipperName]) -> Speedy Express | L12: =_xlfn.XLOOKUP(tbl_FACTS[[#This Row],[ProductID]],Πίνακας7[ProductID],Πίνακας7[ProductName]) -> Louisiana Fiery Hot Pepper Sauce | M12: =_xlfn.XLOOKUP(tbl_FACTS[[#This Row],[ProductID]],Πίνακας7[ProductID],Πίνακας7[CategoryID]) -> 2 | N12: =_xlfn.XLOOKUP(tbl_FACTS[[#This Row],[CategoryID]],Πίνακας4[CategoryID],Πίνακας4[CategoryName]) -> Condiments | O12: =_xlfn.XLOOKUP(tbl_FACTS[[#This Row],[ProductID]],Πίνακας7[ProductID],Πίνακας7[SupplierID]) -> 2 | P12: =_xlfn.XLOOKUP(tbl_FACTS[[#This Row],[SupplierID]],Πίνακας9[SupplierID],Πίνακας9[SupplierName]) -> New Orleans Cajun Delights | Q12: =_xlfn.XLOOKUP(tbl_FACTS[[#This Row],[ProductID]],Πίνακας7[ProductID],Πίνακας7[Price]) -> 21 | R12: =tbl_FACTS[[#This Row],[Quantity]]*tbl_FACTS[[#This Row],[Price]] -> 420 | S12: =IF(COUNTIFS(tbl_FACTS[OrderID],tbl_FACTS[[#This Row],[OrderID]],tbl_FACTS[OrderDetailID],"<"&tbl_FACTS[[#This Row],[OrderDetailID]])=0,1,0) -> 0 | T12: =YEAR(tbl_FACTS[[#This Row],[OrderDate]]) -> 1996 | U12: =DATE(YEAR(tbl_FACTS[[#This Row],[OrderDate]]),MONTH(tbl_FACTS[[#This Row],[OrderDate]]),1) -> 35247 | V12: =IF(tbl_FACTS[[#This Row],[Quantity]]<=10,"0–10",IF(tbl_FACTS[[#This Row],[Quantity]]<=20,"11–20",IF(tbl_FACTS[[#This Row],[Quantity]]<=30,"21–30",IF(tbl_FACTS[[#This Row],[Quantity]]<=40,"31–40",IF(tbl_FACTS[[#This Row],[Quantity]]<=50,"41–50","51+"))))) -> 11–20
A13: 12 | B13: 10252 | C13: 20 | D13: 40 | E13: =_xlfn.XLOOKUP(tbl_FACTS[[#This Row],[OrderID]],Πίνακας64[OrderID],Πίνακας64[OrderDate]) -> 35255 | F13: =_xlfn.XLOOKUP(tbl_FACTS[[#This Row],[OrderID]],Πίνακας64[OrderID],Πίνακας64[CustomerID]) -> 76 | G13: =_xlfn.XLOOKUP(tbl_FACTS[[#This Row],[CustomerID]],Πίνακας1[CustomerID],Πίνακας1[CustomerName]) -> Supremes delices | H13: =_xlfn.XLOOKUP(tbl_FACTS[[#This Row],[CustomerID]],Πίνακας1[CustomerID],Πίνακας1[Country]) -> Belgium | I13: =_xlfn.XLOOKUP(tbl_FACTS[[#This Row],[OrderID]],Πίνακας64[OrderID],Πίνακας64[EmployeeID]) -> 4 | J13: =_xlfn.XLOOKUP(tbl_FACTS[[#This Row],[OrderID]],Πίνακας64[OrderID],Πίνακας64[ShipperID]) -> 2 | K13: =_xlfn.XLOOKUP(tbl_FACTS[[#This Row],[ShipperID]],Πίνακας8[ShipperID],Πίνακας8[ShipperName]) -> United Package | L13: =_xlfn.XLOOKUP(tbl_FACTS[[#This Row],[ProductID]],Πίνακας7[ProductID],Πίνακας7[ProductName]) -> Sir Rodney's Marmalade | M13: =_xlfn.XLOOKUP(tbl_FACTS[[#This Row],[ProductID]],Πίνακας7[ProductID],Πίνακας7[CategoryID]) -> 3 | N13: =_xlfn.XLOOKUP(tbl_FACTS[[#This Row],[CategoryID]],Πίνακας4[CategoryID],Πίνακας4[CategoryName]) -> Confections | O13: =_xlfn.XLOOKUP(tbl_FACTS[[#This Row],[ProductID]],Πίνακας7[ProductID],Πίνακας7[SupplierID]) -> 8 | P13: =_xlfn.XLOOKUP(tbl_FACTS[[#This Row],[SupplierID]],Πίνακας9[SupplierID],Πίνακας9[SupplierName]) -> Specialty Biscuits, Ltd. | Q13: =_xlfn.XLOOKUP(tbl_FACTS[[#This Row],[ProductID]],Πίνακας7[ProductID],Πίνακας7[Price]) -> 81 | R13: =tbl_FACTS[[#This Row],[Quantity]]*tbl_FACTS[[#This Row],[Price]] -> 3240 | S13: =IF(COUNTIFS(tbl_FACTS[OrderID],tbl_FACTS[[#This Row],[OrderID]],tbl_FACTS[OrderDetailID],"<"&tbl_FACTS[[#This Row],[OrderDetailID]])=0,1,0) -> 1 | T13: =YEAR(tbl_FACTS[[#This Row],[OrderDate]]) -> 1996 | U13: =DATE(YEAR(tbl_FACTS[[#This Row],[OrderDate]]),MONTH(tbl_FACTS[[#This Row],[OrderDate]]),1) -> 35247 | V13: =IF(tbl_FACTS[[#This Row],[Quantity]]<=10,"0–10",IF(tbl_FACTS[[#This Row],[Quantity]]<=20,"11–20",IF(tbl_FACTS[[#This Row],[Quantity]]<=30,"21–30",IF(tbl_FACTS[[#This Row],[Quantity]]<=40,"31–40",IF(tbl_FACTS[[#This Row],[Quantity]]<=50,"41–50","51+"))))) -> 31–40
... A519: 518 | B519: 10443 | C519: 28 | D519: 12 | E519: =_xlfn.XLOOKUP(tbl_FACTS[[#This Row],[OrderID]],Πίνακας64[OrderID],Πίνακας64[OrderDate]) -> 35473 | F519: =_xlfn.XLOOKUP(tbl_FACTS[[#This Row],[OrderID]],Πίνακας64[OrderID],Πίνακας64[CustomerID]) -> 66 | G519: =_xlfn.XLOOKUP(tbl_FACTS[[#This Row],[CustomerID]],Πίνακας1[CustomerID],Πίνακας1[CustomerName]) -> Reggiani Caseifici | H519: =_xlfn.XLOOKUP(tbl_FACTS[[#This Row],[CustomerID]],Πίνακας1[CustomerID],Πίνακας1[Country]) -> Italy | I519: =_xlfn.XLOOKUP(tbl_FACTS[[#This Row],[OrderID]],Πίνακας64[OrderID],Πίνακας64[EmployeeID]) -> 8 | J519: =_xlfn.XLOOKUP(tbl_FACTS[[#This Row],[OrderID]],Πίνακας64[OrderID],Πίνακας64[ShipperID]) -> 1 | K519: =_xlfn.XLOOKUP(tbl_FACTS[[#This Row],[ShipperID]],Πίνακας8[ShipperID],Πίνακας8[ShipperName]) -> Speedy Express | L519: =_xlfn.XLOOKUP(tbl_FACTS[[#This Row],[ProductID]],Πίνακας7[ProductID],Πίνακας7[ProductName]) -> Rossle Sauerkraut | M519: =_xlfn.XLOOKUP(tbl_FACTS[[#This Row],[ProductID]],Πίνακας7[ProductID],Πίνακας7[CategoryID]) -> 7 | N519: =_xlfn.XLOOKUP(tbl_FACTS[[#This Row],[CategoryID]],Πίνακας4[CategoryID],Πίνακας4[CategoryName]) -> Produce | O519: =_xlfn.XLOOKUP(tbl_FACTS[[#This Row],[ProductID]],Πίνακας7[ProductID],Πίνακας7[SupplierID]) -> 12 | P519: =_xlfn.XLOOKUP(tbl_FACTS[[#This Row],[SupplierID]],Πίνακας9[SupplierID],Πίνακας9[SupplierName]) -> Plutzer Lebensmittelgro├ƒmarkte AG | Q519: =_xlfn.XLOOKUP(tbl_FACTS[[#This Row],[ProductID]],Πίνακας7[ProductID],Πίνακας7[Price]) -> 46 | R519: =tbl_FACTS[[#This Row],[Quantity]]*tbl_FACTS[[#This Row],[Price]] -> 552 | S519: =IF(COUNTIFS(tbl_FACTS[OrderID],tbl_FACTS[[#This Row],[OrderID]],tbl_FACTS[OrderDetailID],"<"&tbl_FACTS[[#This Row],[OrderDetailID]])=0,1,0) -> 0 | T519: =YEAR(tbl_FACTS[[#This Row],[OrderDate]]) -> 1997 | U519: =DATE(YEAR(tbl_FACTS[[#This Row],[OrderDate]]),MONTH(tbl_FACTS[[#This Row],[OrderDate]]),1) -> 35462 | V519: =IF(tbl_FACTS[[#This Row],[Quantity]]<=10,"0–10",IF(tbl_FACTS[[#This Row],[Quantity]]<=20,"11–20",IF(tbl_FACTS[[#This Row],[Quantity]]<=30,"21–30",IF(tbl_FACTS[[#This Row],[Quantity]]<=40,"31–40",IF(tbl_FACTS[[#This Row],[Quantity]]<=50,"41–50","51+"))))) -> 11–20

Sheet 03_PIVOT
A5: CategoryName | B5: Sum of SalesValue
A6: Beverages | B6: 99699
A7: Condiments | B7: 35024
A8: Confections | B8: 54729
A9: Dairy Products | B9: 70530
A10: Grains/Cereals | B10: 22370
A11: Meat/Poultry | B11: 51636
A12: Produce | B12: 23439
A13: Seafood | B13: 29639
A14: Total | B14: 387066
A16: OrderDate | B16: (Όλα)
A18: Country | B18: Άθροισμα από OrderID | D18: Columns Total (%)
A19: Argentina | B19: 20818 | D19: 15161
A20: Austria | B20: 404353
A21: Belgium | B21: 61662
A22: Brazil | B22: 568678
A23: Canada | B23: 270319
A24: Denmark | B24: 145414
A25: Finland | B25: 154966
A26: France | B26: 455449
A27: Germany | B27: 764797
A28: Ireland | B28: 217201
A29: Italy | B29: 134674
A30: Mexico | B30: 206122
A31: Norway | B31: 41548
... A40: Γενικό Άθροισμα | B40: 5358602
A43: Ετικέτες γραμμής | B43: Καταμέτρηση από OrderID
A44: 0–10 | B44: 132
A45: 11–20 | B45: 163
A46: 21–30 | B46: 91
A47: 31–40 | B47: 55
A48: 41–50 | B48: 33
A49: 51+ | B49: 44
A50: Γενικό Άθροισμα | B50: 518
